2020-07-12 22:28:27,419 INFO: errors [in /Users/amasics/Documents/Full_Stack_Web_Dev/Fresh-Fyyur/backend/app.py:450]
2020-07-12 22:30:57,855 INFO: errors [in /Users/amasics/Documents/Full_Stack_Web_Dev/Fresh-Fyyur/backend/app.py:450]
2020-07-12 22:30:58,150 INFO: errors [in /Users/amasics/Documents/Full_Stack_Web_Dev/Fresh-Fyyur/backend/app.py:450]
2020-07-12 22:31:12,134 ERROR: Exception on /venues/create [GET] [in /Users/amasics/Documents/Full_Stack_Web_Dev/Fresh-Fyyur/env/lib/python3.7/site-packages/flask/app.py:1761]
Traceback (most recent call last):
  File "/Users/amasics/Documents/Full_Stack_Web_Dev/Fresh-Fyyur/env/lib/python3.7/site-packages/flask/app.py", line 2292, in wsgi_app
    response = self.full_dispatch_request()
  File "/Users/amasics/Documents/Full_Stack_Web_Dev/Fresh-Fyyur/env/lib/python3.7/site-packages/flask/app.py", line 1815, in full_dispatch_request
    rv = self.handle_user_exception(e)
  File "/Users/amasics/Documents/Full_Stack_Web_Dev/Fresh-Fyyur/env/lib/python3.7/site-packages/flask_cors/extension.py", line 161, in wrapped_function
    return cors_after_request(app.make_response(f(*args, **kwargs)))
  File "/Users/amasics/Documents/Full_Stack_Web_Dev/Fresh-Fyyur/env/lib/python3.7/site-packages/flask/app.py", line 1718, in handle_user_exception
    reraise(exc_type, exc_value, tb)
  File "/Users/amasics/Documents/Full_Stack_Web_Dev/Fresh-Fyyur/env/lib/python3.7/site-packages/flask/_compat.py", line 35, in reraise
    raise value
  File "/Users/amasics/Documents/Full_Stack_Web_Dev/Fresh-Fyyur/env/lib/python3.7/site-packages/flask/app.py", line 1813, in full_dispatch_request
    rv = self.dispatch_request()
  File "/Users/amasics/Documents/Full_Stack_Web_Dev/Fresh-Fyyur/env/lib/python3.7/site-packages/flask/app.py", line 1799, in dispatch_request
    return self.view_functions[rule.endpoint](**req.view_args)
  File "/Users/amasics/Documents/Full_Stack_Web_Dev/Fresh-Fyyur/backend/app.py", line 152, in create_venue_form
    form = VenueForm()
  File "/Users/amasics/Documents/Full_Stack_Web_Dev/Fresh-Fyyur/env/lib/python3.7/site-packages/wtforms/form.py", line 208, in __call__
    return type.__call__(cls, *args, **kwargs)
  File "/Users/amasics/Documents/Full_Stack_Web_Dev/Fresh-Fyyur/env/lib/python3.7/site-packages/flask_wtf/form.py", line 157, in __init__
    super(Form, self).__init__(*args, **kwargs)
  File "/Users/amasics/Documents/Full_Stack_Web_Dev/Fresh-Fyyur/env/lib/python3.7/site-packages/flask_wtf/form.py", line 87, in __init__
    super(FlaskForm, self).__init__(formdata=formdata, **kwargs)
  File "/Users/amasics/Documents/Full_Stack_Web_Dev/Fresh-Fyyur/env/lib/python3.7/site-packages/wtforms/form.py", line 274, in __init__
    self.process(formdata, obj, data=data, **kwargs)
  File "/Users/amasics/Documents/Full_Stack_Web_Dev/Fresh-Fyyur/env/lib/python3.7/site-packages/wtforms/form.py", line 131, in process
    field.process(formdata)
  File "/Users/amasics/Documents/Full_Stack_Web_Dev/Fresh-Fyyur/env/lib/python3.7/site-packages/wtforms/csrf/core.py", line 43, in process
    self.current_token = self.csrf_impl.generate_csrf_token(self)
  File "/Users/amasics/Documents/Full_Stack_Web_Dev/Fresh-Fyyur/env/lib/python3.7/site-packages/flask_wtf/csrf.py", line 141, in generate_csrf_token
    token_key=self.meta.csrf_field_name
  File "/Users/amasics/Documents/Full_Stack_Web_Dev/Fresh-Fyyur/env/lib/python3.7/site-packages/flask_wtf/csrf.py", line 35, in generate_csrf
    message='A secret key is required to use CSRF.'
  File "/Users/amasics/Documents/Full_Stack_Web_Dev/Fresh-Fyyur/env/lib/python3.7/site-packages/flask_wtf/csrf.py", line 128, in _get_config
    raise RuntimeError(message)
RuntimeError: A secret key is required to use CSRF.
2020-07-12 22:31:14,866 ERROR: Exception on /artists/create [GET] [in /Users/amasics/Documents/Full_Stack_Web_Dev/Fresh-Fyyur/env/lib/python3.7/site-packages/flask/app.py:1761]
Traceback (most recent call last):
  File "/Users/amasics/Documents/Full_Stack_Web_Dev/Fresh-Fyyur/env/lib/python3.7/site-packages/flask/app.py", line 2292, in wsgi_app
    response = self.full_dispatch_request()
  File "/Users/amasics/Documents/Full_Stack_Web_Dev/Fresh-Fyyur/env/lib/python3.7/site-packages/flask/app.py", line 1815, in full_dispatch_request
    rv = self.handle_user_exception(e)
  File "/Users/amasics/Documents/Full_Stack_Web_Dev/Fresh-Fyyur/env/lib/python3.7/site-packages/flask_cors/extension.py", line 161, in wrapped_function
    return cors_after_request(app.make_response(f(*args, **kwargs)))
  File "/Users/amasics/Documents/Full_Stack_Web_Dev/Fresh-Fyyur/env/lib/python3.7/site-packages/flask/app.py", line 1718, in handle_user_exception
    reraise(exc_type, exc_value, tb)
  File "/Users/amasics/Documents/Full_Stack_Web_Dev/Fresh-Fyyur/env/lib/python3.7/site-packages/flask/_compat.py", line 35, in reraise
    raise value
  File "/Users/amasics/Documents/Full_Stack_Web_Dev/Fresh-Fyyur/env/lib/python3.7/site-packages/flask/app.py", line 1813, in full_dispatch_request
    rv = self.dispatch_request()
  File "/Users/amasics/Documents/Full_Stack_Web_Dev/Fresh-Fyyur/env/lib/python3.7/site-packages/flask/app.py", line 1799, in dispatch_request
    return self.view_functions[rule.endpoint](**req.view_args)
  File "/Users/amasics/Documents/Full_Stack_Web_Dev/Fresh-Fyyur/backend/app.py", line 339, in create_artist_form
    form = ArtistForm()
  File "/Users/amasics/Documents/Full_Stack_Web_Dev/Fresh-Fyyur/env/lib/python3.7/site-packages/wtforms/form.py", line 208, in __call__
    return type.__call__(cls, *args, **kwargs)
  File "/Users/amasics/Documents/Full_Stack_Web_Dev/Fresh-Fyyur/env/lib/python3.7/site-packages/flask_wtf/form.py", line 157, in __init__
    super(Form, self).__init__(*args, **kwargs)
  File "/Users/amasics/Documents/Full_Stack_Web_Dev/Fresh-Fyyur/env/lib/python3.7/site-packages/flask_wtf/form.py", line 87, in __init__
    super(FlaskForm, self).__init__(formdata=formdata, **kwargs)
  File "/Users/amasics/Documents/Full_Stack_Web_Dev/Fresh-Fyyur/env/lib/python3.7/site-packages/wtforms/form.py", line 274, in __init__
    self.process(formdata, obj, data=data, **kwargs)
  File "/Users/amasics/Documents/Full_Stack_Web_Dev/Fresh-Fyyur/env/lib/python3.7/site-packages/wtforms/form.py", line 131, in process
    field.process(formdata)
  File "/Users/amasics/Documents/Full_Stack_Web_Dev/Fresh-Fyyur/env/lib/python3.7/site-packages/wtforms/csrf/core.py", line 43, in process
    self.current_token = self.csrf_impl.generate_csrf_token(self)
  File "/Users/amasics/Documents/Full_Stack_Web_Dev/Fresh-Fyyur/env/lib/python3.7/site-packages/flask_wtf/csrf.py", line 141, in generate_csrf_token
    token_key=self.meta.csrf_field_name
  File "/Users/amasics/Documents/Full_Stack_Web_Dev/Fresh-Fyyur/env/lib/python3.7/site-packages/flask_wtf/csrf.py", line 35, in generate_csrf
    message='A secret key is required to use CSRF.'
  File "/Users/amasics/Documents/Full_Stack_Web_Dev/Fresh-Fyyur/env/lib/python3.7/site-packages/flask_wtf/csrf.py", line 128, in _get_config
    raise RuntimeError(message)
RuntimeError: A secret key is required to use CSRF.
2020-07-12 22:31:22,982 ERROR: Exception on /shows/create [GET] [in /Users/amasics/Documents/Full_Stack_Web_Dev/Fresh-Fyyur/env/lib/python3.7/site-packages/flask/app.py:1761]
Traceback (most recent call last):
  File "/Users/amasics/Documents/Full_Stack_Web_Dev/Fresh-Fyyur/env/lib/python3.7/site-packages/flask/app.py", line 2292, in wsgi_app
    response = self.full_dispatch_request()
  File "/Users/amasics/Documents/Full_Stack_Web_Dev/Fresh-Fyyur/env/lib/python3.7/site-packages/flask/app.py", line 1815, in full_dispatch_request
    rv = self.handle_user_exception(e)
  File "/Users/amasics/Documents/Full_Stack_Web_Dev/Fresh-Fyyur/env/lib/python3.7/site-packages/flask_cors/extension.py", line 161, in wrapped_function
    return cors_after_request(app.make_response(f(*args, **kwargs)))
  File "/Users/amasics/Documents/Full_Stack_Web_Dev/Fresh-Fyyur/env/lib/python3.7/site-packages/flask/app.py", line 1718, in handle_user_exception
    reraise(exc_type, exc_value, tb)
  File "/Users/amasics/Documents/Full_Stack_Web_Dev/Fresh-Fyyur/env/lib/python3.7/site-packages/flask/_compat.py", line 35, in reraise
    raise value
  File "/Users/amasics/Documents/Full_Stack_Web_Dev/Fresh-Fyyur/env/lib/python3.7/site-packages/flask/app.py", line 1813, in full_dispatch_request
    rv = self.dispatch_request()
  File "/Users/amasics/Documents/Full_Stack_Web_Dev/Fresh-Fyyur/env/lib/python3.7/site-packages/flask/app.py", line 1799, in dispatch_request
    return self.view_functions[rule.endpoint](**req.view_args)
  File "/Users/amasics/Documents/Full_Stack_Web_Dev/Fresh-Fyyur/backend/app.py", line 407, in create_shows
    form = ShowForm()
  File "/Users/amasics/Documents/Full_Stack_Web_Dev/Fresh-Fyyur/env/lib/python3.7/site-packages/wtforms/form.py", line 208, in __call__
    return type.__call__(cls, *args, **kwargs)
  File "/Users/amasics/Documents/Full_Stack_Web_Dev/Fresh-Fyyur/env/lib/python3.7/site-packages/flask_wtf/form.py", line 157, in __init__
    super(Form, self).__init__(*args, **kwargs)
  File "/Users/amasics/Documents/Full_Stack_Web_Dev/Fresh-Fyyur/env/lib/python3.7/site-packages/flask_wtf/form.py", line 87, in __init__
    super(FlaskForm, self).__init__(formdata=formdata, **kwargs)
  File "/Users/amasics/Documents/Full_Stack_Web_Dev/Fresh-Fyyur/env/lib/python3.7/site-packages/wtforms/form.py", line 274, in __init__
    self.process(formdata, obj, data=data, **kwargs)
  File "/Users/amasics/Documents/Full_Stack_Web_Dev/Fresh-Fyyur/env/lib/python3.7/site-packages/wtforms/form.py", line 131, in process
    field.process(formdata)
  File "/Users/amasics/Documents/Full_Stack_Web_Dev/Fresh-Fyyur/env/lib/python3.7/site-packages/wtforms/csrf/core.py", line 43, in process
    self.current_token = self.csrf_impl.generate_csrf_token(self)
  File "/Users/amasics/Documents/Full_Stack_Web_Dev/Fresh-Fyyur/env/lib/python3.7/site-packages/flask_wtf/csrf.py", line 141, in generate_csrf_token
    token_key=self.meta.csrf_field_name
  File "/Users/amasics/Documents/Full_Stack_Web_Dev/Fresh-Fyyur/env/lib/python3.7/site-packages/flask_wtf/csrf.py", line 35, in generate_csrf
    message='A secret key is required to use CSRF.'
  File "/Users/amasics/Documents/Full_Stack_Web_Dev/Fresh-Fyyur/env/lib/python3.7/site-packages/flask_wtf/csrf.py", line 128, in _get_config
    raise RuntimeError(message)
RuntimeError: A secret key is required to use CSRF.
2020-07-12 22:32:48,655 INFO: errors [in /Users/amasics/Documents/Full_Stack_Web_Dev/Fresh-Fyyur/backend/app.py:450]
2020-07-12 22:33:01,592 ERROR: Exception on /venues/create [GET] [in /Users/amasics/Documents/Full_Stack_Web_Dev/Fresh-Fyyur/env/lib/python3.7/site-packages/flask/app.py:1761]
Traceback (most recent call last):
  File "/Users/amasics/Documents/Full_Stack_Web_Dev/Fresh-Fyyur/env/lib/python3.7/site-packages/flask/app.py", line 2292, in wsgi_app
    response = self.full_dispatch_request()
  File "/Users/amasics/Documents/Full_Stack_Web_Dev/Fresh-Fyyur/env/lib/python3.7/site-packages/flask/app.py", line 1815, in full_dispatch_request
    rv = self.handle_user_exception(e)
  File "/Users/amasics/Documents/Full_Stack_Web_Dev/Fresh-Fyyur/env/lib/python3.7/site-packages/flask/app.py", line 1718, in handle_user_exception
    reraise(exc_type, exc_value, tb)
  File "/Users/amasics/Documents/Full_Stack_Web_Dev/Fresh-Fyyur/env/lib/python3.7/site-packages/flask/_compat.py", line 35, in reraise
    raise value
  File "/Users/amasics/Documents/Full_Stack_Web_Dev/Fresh-Fyyur/env/lib/python3.7/site-packages/flask/app.py", line 1813, in full_dispatch_request
    rv = self.dispatch_request()
  File "/Users/amasics/Documents/Full_Stack_Web_Dev/Fresh-Fyyur/env/lib/python3.7/site-packages/flask/app.py", line 1799, in dispatch_request
    return self.view_functions[rule.endpoint](**req.view_args)
  File "/Users/amasics/Documents/Full_Stack_Web_Dev/Fresh-Fyyur/backend/app.py", line 152, in create_venue_form
    form = VenueForm()
  File "/Users/amasics/Documents/Full_Stack_Web_Dev/Fresh-Fyyur/env/lib/python3.7/site-packages/wtforms/form.py", line 208, in __call__
    return type.__call__(cls, *args, **kwargs)
  File "/Users/amasics/Documents/Full_Stack_Web_Dev/Fresh-Fyyur/env/lib/python3.7/site-packages/flask_wtf/form.py", line 157, in __init__
    super(Form, self).__init__(*args, **kwargs)
  File "/Users/amasics/Documents/Full_Stack_Web_Dev/Fresh-Fyyur/env/lib/python3.7/site-packages/flask_wtf/form.py", line 87, in __init__
    super(FlaskForm, self).__init__(formdata=formdata, **kwargs)
  File "/Users/amasics/Documents/Full_Stack_Web_Dev/Fresh-Fyyur/env/lib/python3.7/site-packages/wtforms/form.py", line 274, in __init__
    self.process(formdata, obj, data=data, **kwargs)
  File "/Users/amasics/Documents/Full_Stack_Web_Dev/Fresh-Fyyur/env/lib/python3.7/site-packages/wtforms/form.py", line 131, in process
    field.process(formdata)
  File "/Users/amasics/Documents/Full_Stack_Web_Dev/Fresh-Fyyur/env/lib/python3.7/site-packages/wtforms/csrf/core.py", line 43, in process
    self.current_token = self.csrf_impl.generate_csrf_token(self)
  File "/Users/amasics/Documents/Full_Stack_Web_Dev/Fresh-Fyyur/env/lib/python3.7/site-packages/flask_wtf/csrf.py", line 141, in generate_csrf_token
    token_key=self.meta.csrf_field_name
  File "/Users/amasics/Documents/Full_Stack_Web_Dev/Fresh-Fyyur/env/lib/python3.7/site-packages/flask_wtf/csrf.py", line 35, in generate_csrf
    message='A secret key is required to use CSRF.'
  File "/Users/amasics/Documents/Full_Stack_Web_Dev/Fresh-Fyyur/env/lib/python3.7/site-packages/flask_wtf/csrf.py", line 128, in _get_config
    raise RuntimeError(message)
RuntimeError: A secret key is required to use CSRF.
2020-07-12 22:33:03,455 ERROR: Exception on /shows/create [GET] [in /Users/amasics/Documents/Full_Stack_Web_Dev/Fresh-Fyyur/env/lib/python3.7/site-packages/flask/app.py:1761]
Traceback (most recent call last):
  File "/Users/amasics/Documents/Full_Stack_Web_Dev/Fresh-Fyyur/env/lib/python3.7/site-packages/flask/app.py", line 2292, in wsgi_app
    response = self.full_dispatch_request()
  File "/Users/amasics/Documents/Full_Stack_Web_Dev/Fresh-Fyyur/env/lib/python3.7/site-packages/flask/app.py", line 1815, in full_dispatch_request
    rv = self.handle_user_exception(e)
  File "/Users/amasics/Documents/Full_Stack_Web_Dev/Fresh-Fyyur/env/lib/python3.7/site-packages/flask/app.py", line 1718, in handle_user_exception
    reraise(exc_type, exc_value, tb)
  File "/Users/amasics/Documents/Full_Stack_Web_Dev/Fresh-Fyyur/env/lib/python3.7/site-packages/flask/_compat.py", line 35, in reraise
    raise value
  File "/Users/amasics/Documents/Full_Stack_Web_Dev/Fresh-Fyyur/env/lib/python3.7/site-packages/flask/app.py", line 1813, in full_dispatch_request
    rv = self.dispatch_request()
  File "/Users/amasics/Documents/Full_Stack_Web_Dev/Fresh-Fyyur/env/lib/python3.7/site-packages/flask/app.py", line 1799, in dispatch_request
    return self.view_functions[rule.endpoint](**req.view_args)
  File "/Users/amasics/Documents/Full_Stack_Web_Dev/Fresh-Fyyur/backend/app.py", line 407, in create_shows
    form = ShowForm()
  File "/Users/amasics/Documents/Full_Stack_Web_Dev/Fresh-Fyyur/env/lib/python3.7/site-packages/wtforms/form.py", line 208, in __call__
    return type.__call__(cls, *args, **kwargs)
  File "/Users/amasics/Documents/Full_Stack_Web_Dev/Fresh-Fyyur/env/lib/python3.7/site-packages/flask_wtf/form.py", line 157, in __init__
    super(Form, self).__init__(*args, **kwargs)
  File "/Users/amasics/Documents/Full_Stack_Web_Dev/Fresh-Fyyur/env/lib/python3.7/site-packages/flask_wtf/form.py", line 87, in __init__
    super(FlaskForm, self).__init__(formdata=formdata, **kwargs)
  File "/Users/amasics/Documents/Full_Stack_Web_Dev/Fresh-Fyyur/env/lib/python3.7/site-packages/wtforms/form.py", line 274, in __init__
    self.process(formdata, obj, data=data, **kwargs)
  File "/Users/amasics/Documents/Full_Stack_Web_Dev/Fresh-Fyyur/env/lib/python3.7/site-packages/wtforms/form.py", line 131, in process
    field.process(formdata)
  File "/Users/amasics/Documents/Full_Stack_Web_Dev/Fresh-Fyyur/env/lib/python3.7/site-packages/wtforms/csrf/core.py", line 43, in process
    self.current_token = self.csrf_impl.generate_csrf_token(self)
  File "/Users/amasics/Documents/Full_Stack_Web_Dev/Fresh-Fyyur/env/lib/python3.7/site-packages/flask_wtf/csrf.py", line 141, in generate_csrf_token
    token_key=self.meta.csrf_field_name
  File "/Users/amasics/Documents/Full_Stack_Web_Dev/Fresh-Fyyur/env/lib/python3.7/site-packages/flask_wtf/csrf.py", line 35, in generate_csrf
    message='A secret key is required to use CSRF.'
  File "/Users/amasics/Documents/Full_Stack_Web_Dev/Fresh-Fyyur/env/lib/python3.7/site-packages/flask_wtf/csrf.py", line 128, in _get_config
    raise RuntimeError(message)
RuntimeError: A secret key is required to use CSRF.
2020-07-12 22:33:15,010 INFO: errors [in /Users/amasics/Documents/Full_Stack_Web_Dev/Fresh-Fyyur/backend/app.py:450]
2020-07-12 22:33:15,277 INFO: errors [in /Users/amasics/Documents/Full_Stack_Web_Dev/Fresh-Fyyur/backend/app.py:450]
2020-07-12 22:33:21,859 INFO: errors [in /Users/amasics/Documents/Full_Stack_Web_Dev/Fresh-Fyyur/backend/app.py:450]
2020-07-12 22:33:31,235 ERROR: Exception on /artists/create [GET] [in /Users/amasics/Documents/Full_Stack_Web_Dev/Fresh-Fyyur/env/lib/python3.7/site-packages/flask/app.py:1761]
Traceback (most recent call last):
  File "/Users/amasics/Documents/Full_Stack_Web_Dev/Fresh-Fyyur/env/lib/python3.7/site-packages/flask/app.py", line 2292, in wsgi_app
    response = self.full_dispatch_request()
  File "/Users/amasics/Documents/Full_Stack_Web_Dev/Fresh-Fyyur/env/lib/python3.7/site-packages/flask/app.py", line 1815, in full_dispatch_request
    rv = self.handle_user_exception(e)
  File "/Users/amasics/Documents/Full_Stack_Web_Dev/Fresh-Fyyur/env/lib/python3.7/site-packages/flask_cors/extension.py", line 161, in wrapped_function
    return cors_after_request(app.make_response(f(*args, **kwargs)))
  File "/Users/amasics/Documents/Full_Stack_Web_Dev/Fresh-Fyyur/env/lib/python3.7/site-packages/flask/app.py", line 1718, in handle_user_exception
    reraise(exc_type, exc_value, tb)
  File "/Users/amasics/Documents/Full_Stack_Web_Dev/Fresh-Fyyur/env/lib/python3.7/site-packages/flask/_compat.py", line 35, in reraise
    raise value
  File "/Users/amasics/Documents/Full_Stack_Web_Dev/Fresh-Fyyur/env/lib/python3.7/site-packages/flask/app.py", line 1813, in full_dispatch_request
    rv = self.dispatch_request()
  File "/Users/amasics/Documents/Full_Stack_Web_Dev/Fresh-Fyyur/env/lib/python3.7/site-packages/flask/app.py", line 1799, in dispatch_request
    return self.view_functions[rule.endpoint](**req.view_args)
  File "/Users/amasics/Documents/Full_Stack_Web_Dev/Fresh-Fyyur/backend/app.py", line 339, in create_artist_form
    form = ArtistForm()
  File "/Users/amasics/Documents/Full_Stack_Web_Dev/Fresh-Fyyur/env/lib/python3.7/site-packages/wtforms/form.py", line 208, in __call__
    return type.__call__(cls, *args, **kwargs)
  File "/Users/amasics/Documents/Full_Stack_Web_Dev/Fresh-Fyyur/env/lib/python3.7/site-packages/flask_wtf/form.py", line 157, in __init__
    super(Form, self).__init__(*args, **kwargs)
  File "/Users/amasics/Documents/Full_Stack_Web_Dev/Fresh-Fyyur/env/lib/python3.7/site-packages/flask_wtf/form.py", line 87, in __init__
    super(FlaskForm, self).__init__(formdata=formdata, **kwargs)
  File "/Users/amasics/Documents/Full_Stack_Web_Dev/Fresh-Fyyur/env/lib/python3.7/site-packages/wtforms/form.py", line 274, in __init__
    self.process(formdata, obj, data=data, **kwargs)
  File "/Users/amasics/Documents/Full_Stack_Web_Dev/Fresh-Fyyur/env/lib/python3.7/site-packages/wtforms/form.py", line 131, in process
    field.process(formdata)
  File "/Users/amasics/Documents/Full_Stack_Web_Dev/Fresh-Fyyur/env/lib/python3.7/site-packages/wtforms/csrf/core.py", line 43, in process
    self.current_token = self.csrf_impl.generate_csrf_token(self)
  File "/Users/amasics/Documents/Full_Stack_Web_Dev/Fresh-Fyyur/env/lib/python3.7/site-packages/flask_wtf/csrf.py", line 141, in generate_csrf_token
    token_key=self.meta.csrf_field_name
  File "/Users/amasics/Documents/Full_Stack_Web_Dev/Fresh-Fyyur/env/lib/python3.7/site-packages/flask_wtf/csrf.py", line 35, in generate_csrf
    message='A secret key is required to use CSRF.'
  File "/Users/amasics/Documents/Full_Stack_Web_Dev/Fresh-Fyyur/env/lib/python3.7/site-packages/flask_wtf/csrf.py", line 128, in _get_config
    raise RuntimeError(message)
RuntimeError: A secret key is required to use CSRF.
2020-07-12 22:34:27,610 INFO: errors [in /Users/amasics/Documents/Full_Stack_Web_Dev/Fresh-Fyyur/backend/app.py:452]
2020-07-12 22:34:35,106 INFO: errors [in /Users/amasics/Documents/Full_Stack_Web_Dev/Fresh-Fyyur/backend/app.py:452]
2020-07-12 22:34:41,094 ERROR: Exception on /venues/create [GET] [in /Users/amasics/Documents/Full_Stack_Web_Dev/Fresh-Fyyur/env/lib/python3.7/site-packages/flask/app.py:1761]
Traceback (most recent call last):
  File "/Users/amasics/Documents/Full_Stack_Web_Dev/Fresh-Fyyur/env/lib/python3.7/site-packages/flask/app.py", line 2292, in wsgi_app
    response = self.full_dispatch_request()
  File "/Users/amasics/Documents/Full_Stack_Web_Dev/Fresh-Fyyur/env/lib/python3.7/site-packages/flask/app.py", line 1815, in full_dispatch_request
    rv = self.handle_user_exception(e)
  File "/Users/amasics/Documents/Full_Stack_Web_Dev/Fresh-Fyyur/env/lib/python3.7/site-packages/flask_cors/extension.py", line 161, in wrapped_function
    return cors_after_request(app.make_response(f(*args, **kwargs)))
  File "/Users/amasics/Documents/Full_Stack_Web_Dev/Fresh-Fyyur/env/lib/python3.7/site-packages/flask/app.py", line 1718, in handle_user_exception
    reraise(exc_type, exc_value, tb)
  File "/Users/amasics/Documents/Full_Stack_Web_Dev/Fresh-Fyyur/env/lib/python3.7/site-packages/flask/_compat.py", line 35, in reraise
    raise value
  File "/Users/amasics/Documents/Full_Stack_Web_Dev/Fresh-Fyyur/env/lib/python3.7/site-packages/flask/app.py", line 1813, in full_dispatch_request
    rv = self.dispatch_request()
  File "/Users/amasics/Documents/Full_Stack_Web_Dev/Fresh-Fyyur/env/lib/python3.7/site-packages/flask/app.py", line 1799, in dispatch_request
    return self.view_functions[rule.endpoint](**req.view_args)
  File "/Users/amasics/Documents/Full_Stack_Web_Dev/Fresh-Fyyur/backend/app.py", line 154, in create_venue_form
    form = VenueForm()
  File "/Users/amasics/Documents/Full_Stack_Web_Dev/Fresh-Fyyur/env/lib/python3.7/site-packages/wtforms/form.py", line 208, in __call__
    return type.__call__(cls, *args, **kwargs)
  File "/Users/amasics/Documents/Full_Stack_Web_Dev/Fresh-Fyyur/env/lib/python3.7/site-packages/flask_wtf/form.py", line 157, in __init__
    super(Form, self).__init__(*args, **kwargs)
  File "/Users/amasics/Documents/Full_Stack_Web_Dev/Fresh-Fyyur/env/lib/python3.7/site-packages/flask_wtf/form.py", line 87, in __init__
    super(FlaskForm, self).__init__(formdata=formdata, **kwargs)
  File "/Users/amasics/Documents/Full_Stack_Web_Dev/Fresh-Fyyur/env/lib/python3.7/site-packages/wtforms/form.py", line 274, in __init__
    self.process(formdata, obj, data=data, **kwargs)
  File "/Users/amasics/Documents/Full_Stack_Web_Dev/Fresh-Fyyur/env/lib/python3.7/site-packages/wtforms/form.py", line 131, in process
    field.process(formdata)
  File "/Users/amasics/Documents/Full_Stack_Web_Dev/Fresh-Fyyur/env/lib/python3.7/site-packages/wtforms/csrf/core.py", line 43, in process
    self.current_token = self.csrf_impl.generate_csrf_token(self)
  File "/Users/amasics/Documents/Full_Stack_Web_Dev/Fresh-Fyyur/env/lib/python3.7/site-packages/flask_wtf/csrf.py", line 141, in generate_csrf_token
    token_key=self.meta.csrf_field_name
  File "/Users/amasics/Documents/Full_Stack_Web_Dev/Fresh-Fyyur/env/lib/python3.7/site-packages/flask_wtf/csrf.py", line 35, in generate_csrf
    message='A secret key is required to use CSRF.'
  File "/Users/amasics/Documents/Full_Stack_Web_Dev/Fresh-Fyyur/env/lib/python3.7/site-packages/flask_wtf/csrf.py", line 128, in _get_config
    raise RuntimeError(message)
RuntimeError: A secret key is required to use CSRF.
2020-07-12 22:35:11,417 INFO: errors [in /Users/amasics/Documents/Full_Stack_Web_Dev/Fresh-Fyyur/backend/app.py:452]
2020-07-12 22:35:11,677 INFO: errors [in /Users/amasics/Documents/Full_Stack_Web_Dev/Fresh-Fyyur/backend/app.py:452]
2020-07-12 22:35:15,845 ERROR: Exception on /venues/create [GET] [in /Users/amasics/Documents/Full_Stack_Web_Dev/Fresh-Fyyur/env/lib/python3.7/site-packages/flask/app.py:1761]
Traceback (most recent call last):
  File "/Users/amasics/Documents/Full_Stack_Web_Dev/Fresh-Fyyur/env/lib/python3.7/site-packages/flask/app.py", line 2292, in wsgi_app
    response = self.full_dispatch_request()
  File "/Users/amasics/Documents/Full_Stack_Web_Dev/Fresh-Fyyur/env/lib/python3.7/site-packages/flask/app.py", line 1815, in full_dispatch_request
    rv = self.handle_user_exception(e)
  File "/Users/amasics/Documents/Full_Stack_Web_Dev/Fresh-Fyyur/env/lib/python3.7/site-packages/flask_cors/extension.py", line 161, in wrapped_function
    return cors_after_request(app.make_response(f(*args, **kwargs)))
  File "/Users/amasics/Documents/Full_Stack_Web_Dev/Fresh-Fyyur/env/lib/python3.7/site-packages/flask/app.py", line 1718, in handle_user_exception
    reraise(exc_type, exc_value, tb)
  File "/Users/amasics/Documents/Full_Stack_Web_Dev/Fresh-Fyyur/env/lib/python3.7/site-packages/flask/_compat.py", line 35, in reraise
    raise value
  File "/Users/amasics/Documents/Full_Stack_Web_Dev/Fresh-Fyyur/env/lib/python3.7/site-packages/flask/app.py", line 1813, in full_dispatch_request
    rv = self.dispatch_request()
  File "/Users/amasics/Documents/Full_Stack_Web_Dev/Fresh-Fyyur/env/lib/python3.7/site-packages/flask/app.py", line 1799, in dispatch_request
    return self.view_functions[rule.endpoint](**req.view_args)
  File "/Users/amasics/Documents/Full_Stack_Web_Dev/Fresh-Fyyur/backend/app.py", line 154, in create_venue_form
    form = VenueForm()
  File "/Users/amasics/Documents/Full_Stack_Web_Dev/Fresh-Fyyur/env/lib/python3.7/site-packages/wtforms/form.py", line 208, in __call__
    return type.__call__(cls, *args, **kwargs)
  File "/Users/amasics/Documents/Full_Stack_Web_Dev/Fresh-Fyyur/env/lib/python3.7/site-packages/flask_wtf/form.py", line 157, in __init__
    super(Form, self).__init__(*args, **kwargs)
  File "/Users/amasics/Documents/Full_Stack_Web_Dev/Fresh-Fyyur/env/lib/python3.7/site-packages/flask_wtf/form.py", line 87, in __init__
    super(FlaskForm, self).__init__(formdata=formdata, **kwargs)
  File "/Users/amasics/Documents/Full_Stack_Web_Dev/Fresh-Fyyur/env/lib/python3.7/site-packages/wtforms/form.py", line 274, in __init__
    self.process(formdata, obj, data=data, **kwargs)
  File "/Users/amasics/Documents/Full_Stack_Web_Dev/Fresh-Fyyur/env/lib/python3.7/site-packages/wtforms/form.py", line 131, in process
    field.process(formdata)
  File "/Users/amasics/Documents/Full_Stack_Web_Dev/Fresh-Fyyur/env/lib/python3.7/site-packages/wtforms/csrf/core.py", line 43, in process
    self.current_token = self.csrf_impl.generate_csrf_token(self)
  File "/Users/amasics/Documents/Full_Stack_Web_Dev/Fresh-Fyyur/env/lib/python3.7/site-packages/flask_wtf/csrf.py", line 141, in generate_csrf_token
    token_key=self.meta.csrf_field_name
  File "/Users/amasics/Documents/Full_Stack_Web_Dev/Fresh-Fyyur/env/lib/python3.7/site-packages/flask_wtf/csrf.py", line 35, in generate_csrf
    message='A secret key is required to use CSRF.'
  File "/Users/amasics/Documents/Full_Stack_Web_Dev/Fresh-Fyyur/env/lib/python3.7/site-packages/flask_wtf/csrf.py", line 128, in _get_config
    raise RuntimeError(message)
RuntimeError: A secret key is required to use CSRF.
2020-07-12 22:35:18,546 ERROR: Exception on /venues/create [GET] [in /Users/amasics/Documents/Full_Stack_Web_Dev/Fresh-Fyyur/env/lib/python3.7/site-packages/flask/app.py:1761]
Traceback (most recent call last):
  File "/Users/amasics/Documents/Full_Stack_Web_Dev/Fresh-Fyyur/env/lib/python3.7/site-packages/flask/app.py", line 2292, in wsgi_app
    response = self.full_dispatch_request()
  File "/Users/amasics/Documents/Full_Stack_Web_Dev/Fresh-Fyyur/env/lib/python3.7/site-packages/flask/app.py", line 1815, in full_dispatch_request
    rv = self.handle_user_exception(e)
  File "/Users/amasics/Documents/Full_Stack_Web_Dev/Fresh-Fyyur/env/lib/python3.7/site-packages/flask_cors/extension.py", line 161, in wrapped_function
    return cors_after_request(app.make_response(f(*args, **kwargs)))
  File "/Users/amasics/Documents/Full_Stack_Web_Dev/Fresh-Fyyur/env/lib/python3.7/site-packages/flask/app.py", line 1718, in handle_user_exception
    reraise(exc_type, exc_value, tb)
  File "/Users/amasics/Documents/Full_Stack_Web_Dev/Fresh-Fyyur/env/lib/python3.7/site-packages/flask/_compat.py", line 35, in reraise
    raise value
  File "/Users/amasics/Documents/Full_Stack_Web_Dev/Fresh-Fyyur/env/lib/python3.7/site-packages/flask/app.py", line 1813, in full_dispatch_request
    rv = self.dispatch_request()
  File "/Users/amasics/Documents/Full_Stack_Web_Dev/Fresh-Fyyur/env/lib/python3.7/site-packages/flask/app.py", line 1799, in dispatch_request
    return self.view_functions[rule.endpoint](**req.view_args)
  File "/Users/amasics/Documents/Full_Stack_Web_Dev/Fresh-Fyyur/backend/app.py", line 154, in create_venue_form
    form = VenueForm()
  File "/Users/amasics/Documents/Full_Stack_Web_Dev/Fresh-Fyyur/env/lib/python3.7/site-packages/wtforms/form.py", line 208, in __call__
    return type.__call__(cls, *args, **kwargs)
  File "/Users/amasics/Documents/Full_Stack_Web_Dev/Fresh-Fyyur/env/lib/python3.7/site-packages/flask_wtf/form.py", line 157, in __init__
    super(Form, self).__init__(*args, **kwargs)
  File "/Users/amasics/Documents/Full_Stack_Web_Dev/Fresh-Fyyur/env/lib/python3.7/site-packages/flask_wtf/form.py", line 87, in __init__
    super(FlaskForm, self).__init__(formdata=formdata, **kwargs)
  File "/Users/amasics/Documents/Full_Stack_Web_Dev/Fresh-Fyyur/env/lib/python3.7/site-packages/wtforms/form.py", line 274, in __init__
    self.process(formdata, obj, data=data, **kwargs)
  File "/Users/amasics/Documents/Full_Stack_Web_Dev/Fresh-Fyyur/env/lib/python3.7/site-packages/wtforms/form.py", line 131, in process
    field.process(formdata)
  File "/Users/amasics/Documents/Full_Stack_Web_Dev/Fresh-Fyyur/env/lib/python3.7/site-packages/wtforms/csrf/core.py", line 43, in process
    self.current_token = self.csrf_impl.generate_csrf_token(self)
  File "/Users/amasics/Documents/Full_Stack_Web_Dev/Fresh-Fyyur/env/lib/python3.7/site-packages/flask_wtf/csrf.py", line 141, in generate_csrf_token
    token_key=self.meta.csrf_field_name
  File "/Users/amasics/Documents/Full_Stack_Web_Dev/Fresh-Fyyur/env/lib/python3.7/site-packages/flask_wtf/csrf.py", line 35, in generate_csrf
    message='A secret key is required to use CSRF.'
  File "/Users/amasics/Documents/Full_Stack_Web_Dev/Fresh-Fyyur/env/lib/python3.7/site-packages/flask_wtf/csrf.py", line 128, in _get_config
    raise RuntimeError(message)
RuntimeError: A secret key is required to use CSRF.
2020-07-12 22:35:36,854 INFO: errors [in /Users/amasics/Documents/Full_Stack_Web_Dev/Fresh-Fyyur/backend/app.py:452]
2020-07-12 22:36:37,754 INFO: errors [in /Users/amasics/Documents/Full_Stack_Web_Dev/Fresh-Fyyur/backend/app.py:452]
2020-07-12 22:36:43,865 INFO: errors [in /Users/amasics/Documents/Full_Stack_Web_Dev/Fresh-Fyyur/backend/app.py:452]
2020-07-12 22:36:56,912 INFO: errors [in /Users/amasics/Documents/Full_Stack_Web_Dev/Fresh-Fyyur/backend/app.py:452]
2020-07-12 22:37:59,254 INFO: errors [in /Users/amasics/Documents/Full_Stack_Web_Dev/Fresh-Fyyur/backend/app.py:452]
2020-07-12 22:40:09,216 INFO: errors [in /Users/amasics/Documents/Full_Stack_Web_Dev/Fresh-Fyyur/backend/app.py:452]
2020-07-12 22:40:16,437 INFO: errors [in /Users/amasics/Documents/Full_Stack_Web_Dev/Fresh-Fyyur/backend/app.py:452]
2020-07-12 22:40:24,889 INFO: errors [in /Users/amasics/Documents/Full_Stack_Web_Dev/Fresh-Fyyur/backend/app.py:452]
2020-07-12 23:12:57,384 INFO: errors [in /Users/amasics/Documents/Full_Stack_Web_Dev/Fresh-Fyyur/backend/app.py:452]
2020-07-12 23:12:57,696 INFO: errors [in /Users/amasics/Documents/Full_Stack_Web_Dev/Fresh-Fyyur/backend/app.py:452]
2020-07-12 23:27:04,904 ERROR: Exception on /venues [GET] [in /Users/amasics/Documents/Full_Stack_Web_Dev/Fresh-Fyyur/env/lib/python3.7/site-packages/flask/app.py:1761]
Traceback (most recent call last):
  File "/Users/amasics/Documents/Full_Stack_Web_Dev/Fresh-Fyyur/env/lib/python3.7/site-packages/sqlalchemy/engine/base.py", line 1244, in _execute_context
    cursor, statement, parameters, context
  File "/Users/amasics/Documents/Full_Stack_Web_Dev/Fresh-Fyyur/env/lib/python3.7/site-packages/sqlalchemy/engine/default.py", line 552, in do_execute
    cursor.execute(statement, parameters)
psycopg2.errors.UndefinedTable: relation "Venue" does not exist
LINE 2: FROM "Venue"
             ^


The above exception was the direct cause of the following exception:

Traceback (most recent call last):
  File "/Users/amasics/Documents/Full_Stack_Web_Dev/Fresh-Fyyur/env/lib/python3.7/site-packages/flask/app.py", line 2292, in wsgi_app
    response = self.full_dispatch_request()
  File "/Users/amasics/Documents/Full_Stack_Web_Dev/Fresh-Fyyur/env/lib/python3.7/site-packages/flask/app.py", line 1815, in full_dispatch_request
    rv = self.handle_user_exception(e)
  File "/Users/amasics/Documents/Full_Stack_Web_Dev/Fresh-Fyyur/env/lib/python3.7/site-packages/flask_cors/extension.py", line 161, in wrapped_function
    return cors_after_request(app.make_response(f(*args, **kwargs)))
  File "/Users/amasics/Documents/Full_Stack_Web_Dev/Fresh-Fyyur/env/lib/python3.7/site-packages/flask/app.py", line 1718, in handle_user_exception
    reraise(exc_type, exc_value, tb)
  File "/Users/amasics/Documents/Full_Stack_Web_Dev/Fresh-Fyyur/env/lib/python3.7/site-packages/flask/_compat.py", line 35, in reraise
    raise value
  File "/Users/amasics/Documents/Full_Stack_Web_Dev/Fresh-Fyyur/env/lib/python3.7/site-packages/flask/app.py", line 1813, in full_dispatch_request
    rv = self.dispatch_request()
  File "/Users/amasics/Documents/Full_Stack_Web_Dev/Fresh-Fyyur/env/lib/python3.7/site-packages/flask/app.py", line 1799, in dispatch_request
    return self.view_functions[rule.endpoint](**req.view_args)
  File "/Users/amasics/Documents/Full_Stack_Web_Dev/Fresh-Fyyur/backend/app.py", line 67, in venues
    cities = Venue.query.distinct('city').all()
  File "/Users/amasics/Documents/Full_Stack_Web_Dev/Fresh-Fyyur/env/lib/python3.7/site-packages/sqlalchemy/orm/query.py", line 3161, in all
    return list(self)
  File "/Users/amasics/Documents/Full_Stack_Web_Dev/Fresh-Fyyur/env/lib/python3.7/site-packages/sqlalchemy/orm/query.py", line 3317, in __iter__
    return self._execute_and_instances(context)
  File "/Users/amasics/Documents/Full_Stack_Web_Dev/Fresh-Fyyur/env/lib/python3.7/site-packages/sqlalchemy/orm/query.py", line 3342, in _execute_and_instances
    result = conn.execute(querycontext.statement, self._params)
  File "/Users/amasics/Documents/Full_Stack_Web_Dev/Fresh-Fyyur/env/lib/python3.7/site-packages/sqlalchemy/engine/base.py", line 988, in execute
    return meth(self, multiparams, params)
  File "/Users/amasics/Documents/Full_Stack_Web_Dev/Fresh-Fyyur/env/lib/python3.7/site-packages/sqlalchemy/sql/elements.py", line 287, in _execute_on_connection
    return connection._execute_clauseelement(self, multiparams, params)
  File "/Users/amasics/Documents/Full_Stack_Web_Dev/Fresh-Fyyur/env/lib/python3.7/site-packages/sqlalchemy/engine/base.py", line 1107, in _execute_clauseelement
    distilled_params,
  File "/Users/amasics/Documents/Full_Stack_Web_Dev/Fresh-Fyyur/env/lib/python3.7/site-packages/sqlalchemy/engine/base.py", line 1248, in _execute_context
    e, statement, parameters, cursor, context
  File "/Users/amasics/Documents/Full_Stack_Web_Dev/Fresh-Fyyur/env/lib/python3.7/site-packages/sqlalchemy/engine/base.py", line 1466, in _handle_dbapi_exception
    util.raise_from_cause(sqlalchemy_exception, exc_info)
  File "/Users/amasics/Documents/Full_Stack_Web_Dev/Fresh-Fyyur/env/lib/python3.7/site-packages/sqlalchemy/util/compat.py", line 383, in raise_from_cause
    reraise(type(exception), exception, tb=exc_tb, cause=cause)
  File "/Users/amasics/Documents/Full_Stack_Web_Dev/Fresh-Fyyur/env/lib/python3.7/site-packages/sqlalchemy/util/compat.py", line 128, in reraise
    raise value.with_traceback(tb)
  File "/Users/amasics/Documents/Full_Stack_Web_Dev/Fresh-Fyyur/env/lib/python3.7/site-packages/sqlalchemy/engine/base.py", line 1244, in _execute_context
    cursor, statement, parameters, context
  File "/Users/amasics/Documents/Full_Stack_Web_Dev/Fresh-Fyyur/env/lib/python3.7/site-packages/sqlalchemy/engine/default.py", line 552, in do_execute
    cursor.execute(statement, parameters)
sqlalchemy.exc.ProgrammingError: (psycopg2.errors.UndefinedTable) relation "Venue" does not exist
LINE 2: FROM "Venue"
             ^

[SQL: SELECT DISTINCT ON ("Venue".city) "Venue".id AS "Venue_id", "Venue".name AS "Venue_name", "Venue".genres AS "Venue_genres", "Venue".city AS "Venue_city", "Venue".state AS "Venue_state", "Venue".address AS "Venue_address", "Venue".phone AS "Venue_phone", "Venue".website AS "Venue_website", "Venue".image_link AS "Venue_image_link", "Venue".facebook_link AS "Venue_facebook_link", "Venue".seeking_talent AS "Venue_seeking_talent", "Venue".seeking_description AS "Venue_seeking_description" 
FROM "Venue"]
(Background on this error at: http://sqlalche.me/e/f405)
2020-07-12 23:27:07,361 ERROR: Exception on /artists [GET] [in /Users/amasics/Documents/Full_Stack_Web_Dev/Fresh-Fyyur/env/lib/python3.7/site-packages/flask/app.py:1761]
Traceback (most recent call last):
  File "/Users/amasics/Documents/Full_Stack_Web_Dev/Fresh-Fyyur/env/lib/python3.7/site-packages/sqlalchemy/engine/base.py", line 1244, in _execute_context
    cursor, statement, parameters, context
  File "/Users/amasics/Documents/Full_Stack_Web_Dev/Fresh-Fyyur/env/lib/python3.7/site-packages/sqlalchemy/engine/default.py", line 552, in do_execute
    cursor.execute(statement, parameters)
psycopg2.errors.UndefinedTable: relation "Artist" does not exist
LINE 2: FROM "Artist" ORDER BY "Artist".id
             ^


The above exception was the direct cause of the following exception:

Traceback (most recent call last):
  File "/Users/amasics/Documents/Full_Stack_Web_Dev/Fresh-Fyyur/env/lib/python3.7/site-packages/flask/app.py", line 2292, in wsgi_app
    response = self.full_dispatch_request()
  File "/Users/amasics/Documents/Full_Stack_Web_Dev/Fresh-Fyyur/env/lib/python3.7/site-packages/flask/app.py", line 1815, in full_dispatch_request
    rv = self.handle_user_exception(e)
  File "/Users/amasics/Documents/Full_Stack_Web_Dev/Fresh-Fyyur/env/lib/python3.7/site-packages/flask_cors/extension.py", line 161, in wrapped_function
    return cors_after_request(app.make_response(f(*args, **kwargs)))
  File "/Users/amasics/Documents/Full_Stack_Web_Dev/Fresh-Fyyur/env/lib/python3.7/site-packages/flask/app.py", line 1718, in handle_user_exception
    reraise(exc_type, exc_value, tb)
  File "/Users/amasics/Documents/Full_Stack_Web_Dev/Fresh-Fyyur/env/lib/python3.7/site-packages/flask/_compat.py", line 35, in reraise
    raise value
  File "/Users/amasics/Documents/Full_Stack_Web_Dev/Fresh-Fyyur/env/lib/python3.7/site-packages/flask/app.py", line 1813, in full_dispatch_request
    rv = self.dispatch_request()
  File "/Users/amasics/Documents/Full_Stack_Web_Dev/Fresh-Fyyur/env/lib/python3.7/site-packages/flask/app.py", line 1799, in dispatch_request
    return self.view_functions[rule.endpoint](**req.view_args)
  File "/Users/amasics/Documents/Full_Stack_Web_Dev/Fresh-Fyyur/backend/app.py", line 214, in artists
    for artist in Artist.query.order_by('id').all():
  File "/Users/amasics/Documents/Full_Stack_Web_Dev/Fresh-Fyyur/env/lib/python3.7/site-packages/sqlalchemy/orm/query.py", line 3161, in all
    return list(self)
  File "/Users/amasics/Documents/Full_Stack_Web_Dev/Fresh-Fyyur/env/lib/python3.7/site-packages/sqlalchemy/orm/query.py", line 3317, in __iter__
    return self._execute_and_instances(context)
  File "/Users/amasics/Documents/Full_Stack_Web_Dev/Fresh-Fyyur/env/lib/python3.7/site-packages/sqlalchemy/orm/query.py", line 3342, in _execute_and_instances
    result = conn.execute(querycontext.statement, self._params)
  File "/Users/amasics/Documents/Full_Stack_Web_Dev/Fresh-Fyyur/env/lib/python3.7/site-packages/sqlalchemy/engine/base.py", line 988, in execute
    return meth(self, multiparams, params)
  File "/Users/amasics/Documents/Full_Stack_Web_Dev/Fresh-Fyyur/env/lib/python3.7/site-packages/sqlalchemy/sql/elements.py", line 287, in _execute_on_connection
    return connection._execute_clauseelement(self, multiparams, params)
  File "/Users/amasics/Documents/Full_Stack_Web_Dev/Fresh-Fyyur/env/lib/python3.7/site-packages/sqlalchemy/engine/base.py", line 1107, in _execute_clauseelement
    distilled_params,
  File "/Users/amasics/Documents/Full_Stack_Web_Dev/Fresh-Fyyur/env/lib/python3.7/site-packages/sqlalchemy/engine/base.py", line 1248, in _execute_context
    e, statement, parameters, cursor, context
  File "/Users/amasics/Documents/Full_Stack_Web_Dev/Fresh-Fyyur/env/lib/python3.7/site-packages/sqlalchemy/engine/base.py", line 1466, in _handle_dbapi_exception
    util.raise_from_cause(sqlalchemy_exception, exc_info)
  File "/Users/amasics/Documents/Full_Stack_Web_Dev/Fresh-Fyyur/env/lib/python3.7/site-packages/sqlalchemy/util/compat.py", line 383, in raise_from_cause
    reraise(type(exception), exception, tb=exc_tb, cause=cause)
  File "/Users/amasics/Documents/Full_Stack_Web_Dev/Fresh-Fyyur/env/lib/python3.7/site-packages/sqlalchemy/util/compat.py", line 128, in reraise
    raise value.with_traceback(tb)
  File "/Users/amasics/Documents/Full_Stack_Web_Dev/Fresh-Fyyur/env/lib/python3.7/site-packages/sqlalchemy/engine/base.py", line 1244, in _execute_context
    cursor, statement, parameters, context
  File "/Users/amasics/Documents/Full_Stack_Web_Dev/Fresh-Fyyur/env/lib/python3.7/site-packages/sqlalchemy/engine/default.py", line 552, in do_execute
    cursor.execute(statement, parameters)
sqlalchemy.exc.ProgrammingError: (psycopg2.errors.UndefinedTable) relation "Artist" does not exist
LINE 2: FROM "Artist" ORDER BY "Artist".id
             ^

[SQL: SELECT "Artist".id AS "Artist_id", "Artist".name AS "Artist_name", "Artist".city AS "Artist_city", "Artist".state AS "Artist_state", "Artist".phone AS "Artist_phone", "Artist".genres AS "Artist_genres", "Artist".website AS "Artist_website", "Artist".image_link AS "Artist_image_link", "Artist".facebook_link AS "Artist_facebook_link", "Artist".seeking_venue AS "Artist_seeking_venue", "Artist".seeking_description AS "Artist_seeking_description" 
FROM "Artist" ORDER BY "Artist".id]
(Background on this error at: http://sqlalche.me/e/f405)
2020-07-12 23:27:10,178 ERROR: Exception on /venues [GET] [in /Users/amasics/Documents/Full_Stack_Web_Dev/Fresh-Fyyur/env/lib/python3.7/site-packages/flask/app.py:1761]
Traceback (most recent call last):
  File "/Users/amasics/Documents/Full_Stack_Web_Dev/Fresh-Fyyur/env/lib/python3.7/site-packages/sqlalchemy/engine/base.py", line 1244, in _execute_context
    cursor, statement, parameters, context
  File "/Users/amasics/Documents/Full_Stack_Web_Dev/Fresh-Fyyur/env/lib/python3.7/site-packages/sqlalchemy/engine/default.py", line 552, in do_execute
    cursor.execute(statement, parameters)
psycopg2.errors.UndefinedTable: relation "Venue" does not exist
LINE 2: FROM "Venue"
             ^


The above exception was the direct cause of the following exception:

Traceback (most recent call last):
  File "/Users/amasics/Documents/Full_Stack_Web_Dev/Fresh-Fyyur/env/lib/python3.7/site-packages/flask/app.py", line 2292, in wsgi_app
    response = self.full_dispatch_request()
  File "/Users/amasics/Documents/Full_Stack_Web_Dev/Fresh-Fyyur/env/lib/python3.7/site-packages/flask/app.py", line 1815, in full_dispatch_request
    rv = self.handle_user_exception(e)
  File "/Users/amasics/Documents/Full_Stack_Web_Dev/Fresh-Fyyur/env/lib/python3.7/site-packages/flask_cors/extension.py", line 161, in wrapped_function
    return cors_after_request(app.make_response(f(*args, **kwargs)))
  File "/Users/amasics/Documents/Full_Stack_Web_Dev/Fresh-Fyyur/env/lib/python3.7/site-packages/flask/app.py", line 1718, in handle_user_exception
    reraise(exc_type, exc_value, tb)
  File "/Users/amasics/Documents/Full_Stack_Web_Dev/Fresh-Fyyur/env/lib/python3.7/site-packages/flask/_compat.py", line 35, in reraise
    raise value
  File "/Users/amasics/Documents/Full_Stack_Web_Dev/Fresh-Fyyur/env/lib/python3.7/site-packages/flask/app.py", line 1813, in full_dispatch_request
    rv = self.dispatch_request()
  File "/Users/amasics/Documents/Full_Stack_Web_Dev/Fresh-Fyyur/env/lib/python3.7/site-packages/flask/app.py", line 1799, in dispatch_request
    return self.view_functions[rule.endpoint](**req.view_args)
  File "/Users/amasics/Documents/Full_Stack_Web_Dev/Fresh-Fyyur/backend/app.py", line 67, in venues
    cities = Venue.query.distinct('city').all()
  File "/Users/amasics/Documents/Full_Stack_Web_Dev/Fresh-Fyyur/env/lib/python3.7/site-packages/sqlalchemy/orm/query.py", line 3161, in all
    return list(self)
  File "/Users/amasics/Documents/Full_Stack_Web_Dev/Fresh-Fyyur/env/lib/python3.7/site-packages/sqlalchemy/orm/query.py", line 3317, in __iter__
    return self._execute_and_instances(context)
  File "/Users/amasics/Documents/Full_Stack_Web_Dev/Fresh-Fyyur/env/lib/python3.7/site-packages/sqlalchemy/orm/query.py", line 3342, in _execute_and_instances
    result = conn.execute(querycontext.statement, self._params)
  File "/Users/amasics/Documents/Full_Stack_Web_Dev/Fresh-Fyyur/env/lib/python3.7/site-packages/sqlalchemy/engine/base.py", line 988, in execute
    return meth(self, multiparams, params)
  File "/Users/amasics/Documents/Full_Stack_Web_Dev/Fresh-Fyyur/env/lib/python3.7/site-packages/sqlalchemy/sql/elements.py", line 287, in _execute_on_connection
    return connection._execute_clauseelement(self, multiparams, params)
  File "/Users/amasics/Documents/Full_Stack_Web_Dev/Fresh-Fyyur/env/lib/python3.7/site-packages/sqlalchemy/engine/base.py", line 1107, in _execute_clauseelement
    distilled_params,
  File "/Users/amasics/Documents/Full_Stack_Web_Dev/Fresh-Fyyur/env/lib/python3.7/site-packages/sqlalchemy/engine/base.py", line 1248, in _execute_context
    e, statement, parameters, cursor, context
  File "/Users/amasics/Documents/Full_Stack_Web_Dev/Fresh-Fyyur/env/lib/python3.7/site-packages/sqlalchemy/engine/base.py", line 1466, in _handle_dbapi_exception
    util.raise_from_cause(sqlalchemy_exception, exc_info)
  File "/Users/amasics/Documents/Full_Stack_Web_Dev/Fresh-Fyyur/env/lib/python3.7/site-packages/sqlalchemy/util/compat.py", line 383, in raise_from_cause
    reraise(type(exception), exception, tb=exc_tb, cause=cause)
  File "/Users/amasics/Documents/Full_Stack_Web_Dev/Fresh-Fyyur/env/lib/python3.7/site-packages/sqlalchemy/util/compat.py", line 128, in reraise
    raise value.with_traceback(tb)
  File "/Users/amasics/Documents/Full_Stack_Web_Dev/Fresh-Fyyur/env/lib/python3.7/site-packages/sqlalchemy/engine/base.py", line 1244, in _execute_context
    cursor, statement, parameters, context
  File "/Users/amasics/Documents/Full_Stack_Web_Dev/Fresh-Fyyur/env/lib/python3.7/site-packages/sqlalchemy/engine/default.py", line 552, in do_execute
    cursor.execute(statement, parameters)
sqlalchemy.exc.ProgrammingError: (psycopg2.errors.UndefinedTable) relation "Venue" does not exist
LINE 2: FROM "Venue"
             ^

[SQL: SELECT DISTINCT ON ("Venue".city) "Venue".id AS "Venue_id", "Venue".name AS "Venue_name", "Venue".genres AS "Venue_genres", "Venue".city AS "Venue_city", "Venue".state AS "Venue_state", "Venue".address AS "Venue_address", "Venue".phone AS "Venue_phone", "Venue".website AS "Venue_website", "Venue".image_link AS "Venue_image_link", "Venue".facebook_link AS "Venue_facebook_link", "Venue".seeking_talent AS "Venue_seeking_talent", "Venue".seeking_description AS "Venue_seeking_description" 
FROM "Venue"]
(Background on this error at: http://sqlalche.me/e/f405)
2020-07-12 23:28:19,495 ERROR: Exception on /venues [GET] [in /Users/amasics/Documents/Full_Stack_Web_Dev/Fresh-Fyyur/env/lib/python3.7/site-packages/flask/app.py:1761]
Traceback (most recent call last):
  File "/Users/amasics/Documents/Full_Stack_Web_Dev/Fresh-Fyyur/env/lib/python3.7/site-packages/sqlalchemy/engine/base.py", line 1244, in _execute_context
    cursor, statement, parameters, context
  File "/Users/amasics/Documents/Full_Stack_Web_Dev/Fresh-Fyyur/env/lib/python3.7/site-packages/sqlalchemy/engine/default.py", line 552, in do_execute
    cursor.execute(statement, parameters)
psycopg2.errors.UndefinedTable: relation "Venue" does not exist
LINE 2: FROM "Venue"
             ^


The above exception was the direct cause of the following exception:

Traceback (most recent call last):
  File "/Users/amasics/Documents/Full_Stack_Web_Dev/Fresh-Fyyur/env/lib/python3.7/site-packages/flask/app.py", line 2292, in wsgi_app
    response = self.full_dispatch_request()
  File "/Users/amasics/Documents/Full_Stack_Web_Dev/Fresh-Fyyur/env/lib/python3.7/site-packages/flask/app.py", line 1815, in full_dispatch_request
    rv = self.handle_user_exception(e)
  File "/Users/amasics/Documents/Full_Stack_Web_Dev/Fresh-Fyyur/env/lib/python3.7/site-packages/flask_cors/extension.py", line 161, in wrapped_function
    return cors_after_request(app.make_response(f(*args, **kwargs)))
  File "/Users/amasics/Documents/Full_Stack_Web_Dev/Fresh-Fyyur/env/lib/python3.7/site-packages/flask/app.py", line 1718, in handle_user_exception
    reraise(exc_type, exc_value, tb)
  File "/Users/amasics/Documents/Full_Stack_Web_Dev/Fresh-Fyyur/env/lib/python3.7/site-packages/flask/_compat.py", line 35, in reraise
    raise value
  File "/Users/amasics/Documents/Full_Stack_Web_Dev/Fresh-Fyyur/env/lib/python3.7/site-packages/flask/app.py", line 1813, in full_dispatch_request
    rv = self.dispatch_request()
  File "/Users/amasics/Documents/Full_Stack_Web_Dev/Fresh-Fyyur/env/lib/python3.7/site-packages/flask/app.py", line 1799, in dispatch_request
    return self.view_functions[rule.endpoint](**req.view_args)
  File "/Users/amasics/Documents/Full_Stack_Web_Dev/Fresh-Fyyur/backend/app.py", line 67, in venues
    cities = Venue.query.distinct('city').all()
  File "/Users/amasics/Documents/Full_Stack_Web_Dev/Fresh-Fyyur/env/lib/python3.7/site-packages/sqlalchemy/orm/query.py", line 3161, in all
    return list(self)
  File "/Users/amasics/Documents/Full_Stack_Web_Dev/Fresh-Fyyur/env/lib/python3.7/site-packages/sqlalchemy/orm/query.py", line 3317, in __iter__
    return self._execute_and_instances(context)
  File "/Users/amasics/Documents/Full_Stack_Web_Dev/Fresh-Fyyur/env/lib/python3.7/site-packages/sqlalchemy/orm/query.py", line 3342, in _execute_and_instances
    result = conn.execute(querycontext.statement, self._params)
  File "/Users/amasics/Documents/Full_Stack_Web_Dev/Fresh-Fyyur/env/lib/python3.7/site-packages/sqlalchemy/engine/base.py", line 988, in execute
    return meth(self, multiparams, params)
  File "/Users/amasics/Documents/Full_Stack_Web_Dev/Fresh-Fyyur/env/lib/python3.7/site-packages/sqlalchemy/sql/elements.py", line 287, in _execute_on_connection
    return connection._execute_clauseelement(self, multiparams, params)
  File "/Users/amasics/Documents/Full_Stack_Web_Dev/Fresh-Fyyur/env/lib/python3.7/site-packages/sqlalchemy/engine/base.py", line 1107, in _execute_clauseelement
    distilled_params,
  File "/Users/amasics/Documents/Full_Stack_Web_Dev/Fresh-Fyyur/env/lib/python3.7/site-packages/sqlalchemy/engine/base.py", line 1248, in _execute_context
    e, statement, parameters, cursor, context
  File "/Users/amasics/Documents/Full_Stack_Web_Dev/Fresh-Fyyur/env/lib/python3.7/site-packages/sqlalchemy/engine/base.py", line 1466, in _handle_dbapi_exception
    util.raise_from_cause(sqlalchemy_exception, exc_info)
  File "/Users/amasics/Documents/Full_Stack_Web_Dev/Fresh-Fyyur/env/lib/python3.7/site-packages/sqlalchemy/util/compat.py", line 383, in raise_from_cause
    reraise(type(exception), exception, tb=exc_tb, cause=cause)
  File "/Users/amasics/Documents/Full_Stack_Web_Dev/Fresh-Fyyur/env/lib/python3.7/site-packages/sqlalchemy/util/compat.py", line 128, in reraise
    raise value.with_traceback(tb)
  File "/Users/amasics/Documents/Full_Stack_Web_Dev/Fresh-Fyyur/env/lib/python3.7/site-packages/sqlalchemy/engine/base.py", line 1244, in _execute_context
    cursor, statement, parameters, context
  File "/Users/amasics/Documents/Full_Stack_Web_Dev/Fresh-Fyyur/env/lib/python3.7/site-packages/sqlalchemy/engine/default.py", line 552, in do_execute
    cursor.execute(statement, parameters)
sqlalchemy.exc.ProgrammingError: (psycopg2.errors.UndefinedTable) relation "Venue" does not exist
LINE 2: FROM "Venue"
             ^

[SQL: SELECT DISTINCT ON ("Venue".city) "Venue".id AS "Venue_id", "Venue".name AS "Venue_name", "Venue".genres AS "Venue_genres", "Venue".city AS "Venue_city", "Venue".state AS "Venue_state", "Venue".address AS "Venue_address", "Venue".phone AS "Venue_phone", "Venue".website AS "Venue_website", "Venue".image_link AS "Venue_image_link", "Venue".facebook_link AS "Venue_facebook_link", "Venue".seeking_talent AS "Venue_seeking_talent", "Venue".seeking_description AS "Venue_seeking_description" 
FROM "Venue"]
(Background on this error at: http://sqlalche.me/e/f405)
2020-07-12 23:30:10,338 INFO: errors [in /Users/amasics/Documents/Full_Stack_Web_Dev/Fresh-Fyyur/backend/app.py:452]
2020-07-12 23:30:10,665 INFO: errors [in /Users/amasics/Documents/Full_Stack_Web_Dev/Fresh-Fyyur/backend/app.py:452]
2020-07-12 23:30:12,807 ERROR: Exception on /venues [GET] [in /Users/amasics/Documents/Full_Stack_Web_Dev/Fresh-Fyyur/env/lib/python3.7/site-packages/flask/app.py:1761]
Traceback (most recent call last):
  File "/Users/amasics/Documents/Full_Stack_Web_Dev/Fresh-Fyyur/env/lib/python3.7/site-packages/sqlalchemy/engine/base.py", line 1244, in _execute_context
    cursor, statement, parameters, context
  File "/Users/amasics/Documents/Full_Stack_Web_Dev/Fresh-Fyyur/env/lib/python3.7/site-packages/sqlalchemy/engine/default.py", line 552, in do_execute
    cursor.execute(statement, parameters)
psycopg2.errors.UndefinedTable: relation "Venue" does not exist
LINE 2: FROM "Venue"
             ^


The above exception was the direct cause of the following exception:

Traceback (most recent call last):
  File "/Users/amasics/Documents/Full_Stack_Web_Dev/Fresh-Fyyur/env/lib/python3.7/site-packages/flask/app.py", line 2292, in wsgi_app
    response = self.full_dispatch_request()
  File "/Users/amasics/Documents/Full_Stack_Web_Dev/Fresh-Fyyur/env/lib/python3.7/site-packages/flask/app.py", line 1815, in full_dispatch_request
    rv = self.handle_user_exception(e)
  File "/Users/amasics/Documents/Full_Stack_Web_Dev/Fresh-Fyyur/env/lib/python3.7/site-packages/flask_cors/extension.py", line 161, in wrapped_function
    return cors_after_request(app.make_response(f(*args, **kwargs)))
  File "/Users/amasics/Documents/Full_Stack_Web_Dev/Fresh-Fyyur/env/lib/python3.7/site-packages/flask/app.py", line 1718, in handle_user_exception
    reraise(exc_type, exc_value, tb)
  File "/Users/amasics/Documents/Full_Stack_Web_Dev/Fresh-Fyyur/env/lib/python3.7/site-packages/flask/_compat.py", line 35, in reraise
    raise value
  File "/Users/amasics/Documents/Full_Stack_Web_Dev/Fresh-Fyyur/env/lib/python3.7/site-packages/flask/app.py", line 1813, in full_dispatch_request
    rv = self.dispatch_request()
  File "/Users/amasics/Documents/Full_Stack_Web_Dev/Fresh-Fyyur/env/lib/python3.7/site-packages/flask/app.py", line 1799, in dispatch_request
    return self.view_functions[rule.endpoint](**req.view_args)
  File "/Users/amasics/Documents/Full_Stack_Web_Dev/Fresh-Fyyur/backend/app.py", line 67, in venues
    cities = Venue.query.distinct('city').all()
  File "/Users/amasics/Documents/Full_Stack_Web_Dev/Fresh-Fyyur/env/lib/python3.7/site-packages/sqlalchemy/orm/query.py", line 3161, in all
    return list(self)
  File "/Users/amasics/Documents/Full_Stack_Web_Dev/Fresh-Fyyur/env/lib/python3.7/site-packages/sqlalchemy/orm/query.py", line 3317, in __iter__
    return self._execute_and_instances(context)
  File "/Users/amasics/Documents/Full_Stack_Web_Dev/Fresh-Fyyur/env/lib/python3.7/site-packages/sqlalchemy/orm/query.py", line 3342, in _execute_and_instances
    result = conn.execute(querycontext.statement, self._params)
  File "/Users/amasics/Documents/Full_Stack_Web_Dev/Fresh-Fyyur/env/lib/python3.7/site-packages/sqlalchemy/engine/base.py", line 988, in execute
    return meth(self, multiparams, params)
  File "/Users/amasics/Documents/Full_Stack_Web_Dev/Fresh-Fyyur/env/lib/python3.7/site-packages/sqlalchemy/sql/elements.py", line 287, in _execute_on_connection
    return connection._execute_clauseelement(self, multiparams, params)
  File "/Users/amasics/Documents/Full_Stack_Web_Dev/Fresh-Fyyur/env/lib/python3.7/site-packages/sqlalchemy/engine/base.py", line 1107, in _execute_clauseelement
    distilled_params,
  File "/Users/amasics/Documents/Full_Stack_Web_Dev/Fresh-Fyyur/env/lib/python3.7/site-packages/sqlalchemy/engine/base.py", line 1248, in _execute_context
    e, statement, parameters, cursor, context
  File "/Users/amasics/Documents/Full_Stack_Web_Dev/Fresh-Fyyur/env/lib/python3.7/site-packages/sqlalchemy/engine/base.py", line 1466, in _handle_dbapi_exception
    util.raise_from_cause(sqlalchemy_exception, exc_info)
  File "/Users/amasics/Documents/Full_Stack_Web_Dev/Fresh-Fyyur/env/lib/python3.7/site-packages/sqlalchemy/util/compat.py", line 383, in raise_from_cause
    reraise(type(exception), exception, tb=exc_tb, cause=cause)
  File "/Users/amasics/Documents/Full_Stack_Web_Dev/Fresh-Fyyur/env/lib/python3.7/site-packages/sqlalchemy/util/compat.py", line 128, in reraise
    raise value.with_traceback(tb)
  File "/Users/amasics/Documents/Full_Stack_Web_Dev/Fresh-Fyyur/env/lib/python3.7/site-packages/sqlalchemy/engine/base.py", line 1244, in _execute_context
    cursor, statement, parameters, context
  File "/Users/amasics/Documents/Full_Stack_Web_Dev/Fresh-Fyyur/env/lib/python3.7/site-packages/sqlalchemy/engine/default.py", line 552, in do_execute
    cursor.execute(statement, parameters)
sqlalchemy.exc.ProgrammingError: (psycopg2.errors.UndefinedTable) relation "Venue" does not exist
LINE 2: FROM "Venue"
             ^

[SQL: SELECT DISTINCT ON ("Venue".city) "Venue".id AS "Venue_id", "Venue".name AS "Venue_name", "Venue".genres AS "Venue_genres", "Venue".city AS "Venue_city", "Venue".state AS "Venue_state", "Venue".address AS "Venue_address", "Venue".phone AS "Venue_phone", "Venue".website AS "Venue_website", "Venue".image_link AS "Venue_image_link", "Venue".facebook_link AS "Venue_facebook_link", "Venue".seeking_talent AS "Venue_seeking_talent", "Venue".seeking_description AS "Venue_seeking_description" 
FROM "Venue"]
(Background on this error at: http://sqlalche.me/e/f405)
2020-07-12 23:30:15,462 ERROR: Exception on /venues [GET] [in /Users/amasics/Documents/Full_Stack_Web_Dev/Fresh-Fyyur/env/lib/python3.7/site-packages/flask/app.py:1761]
Traceback (most recent call last):
  File "/Users/amasics/Documents/Full_Stack_Web_Dev/Fresh-Fyyur/env/lib/python3.7/site-packages/sqlalchemy/engine/base.py", line 1244, in _execute_context
    cursor, statement, parameters, context
  File "/Users/amasics/Documents/Full_Stack_Web_Dev/Fresh-Fyyur/env/lib/python3.7/site-packages/sqlalchemy/engine/default.py", line 552, in do_execute
    cursor.execute(statement, parameters)
psycopg2.errors.UndefinedTable: relation "Venue" does not exist
LINE 2: FROM "Venue"
             ^


The above exception was the direct cause of the following exception:

Traceback (most recent call last):
  File "/Users/amasics/Documents/Full_Stack_Web_Dev/Fresh-Fyyur/env/lib/python3.7/site-packages/flask/app.py", line 2292, in wsgi_app
    response = self.full_dispatch_request()
  File "/Users/amasics/Documents/Full_Stack_Web_Dev/Fresh-Fyyur/env/lib/python3.7/site-packages/flask/app.py", line 1815, in full_dispatch_request
    rv = self.handle_user_exception(e)
  File "/Users/amasics/Documents/Full_Stack_Web_Dev/Fresh-Fyyur/env/lib/python3.7/site-packages/flask_cors/extension.py", line 161, in wrapped_function
    return cors_after_request(app.make_response(f(*args, **kwargs)))
  File "/Users/amasics/Documents/Full_Stack_Web_Dev/Fresh-Fyyur/env/lib/python3.7/site-packages/flask/app.py", line 1718, in handle_user_exception
    reraise(exc_type, exc_value, tb)
  File "/Users/amasics/Documents/Full_Stack_Web_Dev/Fresh-Fyyur/env/lib/python3.7/site-packages/flask/_compat.py", line 35, in reraise
    raise value
  File "/Users/amasics/Documents/Full_Stack_Web_Dev/Fresh-Fyyur/env/lib/python3.7/site-packages/flask/app.py", line 1813, in full_dispatch_request
    rv = self.dispatch_request()
  File "/Users/amasics/Documents/Full_Stack_Web_Dev/Fresh-Fyyur/env/lib/python3.7/site-packages/flask/app.py", line 1799, in dispatch_request
    return self.view_functions[rule.endpoint](**req.view_args)
  File "/Users/amasics/Documents/Full_Stack_Web_Dev/Fresh-Fyyur/backend/app.py", line 67, in venues
    cities = Venue.query.distinct('city').all()
  File "/Users/amasics/Documents/Full_Stack_Web_Dev/Fresh-Fyyur/env/lib/python3.7/site-packages/sqlalchemy/orm/query.py", line 3161, in all
    return list(self)
  File "/Users/amasics/Documents/Full_Stack_Web_Dev/Fresh-Fyyur/env/lib/python3.7/site-packages/sqlalchemy/orm/query.py", line 3317, in __iter__
    return self._execute_and_instances(context)
  File "/Users/amasics/Documents/Full_Stack_Web_Dev/Fresh-Fyyur/env/lib/python3.7/site-packages/sqlalchemy/orm/query.py", line 3342, in _execute_and_instances
    result = conn.execute(querycontext.statement, self._params)
  File "/Users/amasics/Documents/Full_Stack_Web_Dev/Fresh-Fyyur/env/lib/python3.7/site-packages/sqlalchemy/engine/base.py", line 988, in execute
    return meth(self, multiparams, params)
  File "/Users/amasics/Documents/Full_Stack_Web_Dev/Fresh-Fyyur/env/lib/python3.7/site-packages/sqlalchemy/sql/elements.py", line 287, in _execute_on_connection
    return connection._execute_clauseelement(self, multiparams, params)
  File "/Users/amasics/Documents/Full_Stack_Web_Dev/Fresh-Fyyur/env/lib/python3.7/site-packages/sqlalchemy/engine/base.py", line 1107, in _execute_clauseelement
    distilled_params,
  File "/Users/amasics/Documents/Full_Stack_Web_Dev/Fresh-Fyyur/env/lib/python3.7/site-packages/sqlalchemy/engine/base.py", line 1248, in _execute_context
    e, statement, parameters, cursor, context
  File "/Users/amasics/Documents/Full_Stack_Web_Dev/Fresh-Fyyur/env/lib/python3.7/site-packages/sqlalchemy/engine/base.py", line 1466, in _handle_dbapi_exception
    util.raise_from_cause(sqlalchemy_exception, exc_info)
  File "/Users/amasics/Documents/Full_Stack_Web_Dev/Fresh-Fyyur/env/lib/python3.7/site-packages/sqlalchemy/util/compat.py", line 383, in raise_from_cause
    reraise(type(exception), exception, tb=exc_tb, cause=cause)
  File "/Users/amasics/Documents/Full_Stack_Web_Dev/Fresh-Fyyur/env/lib/python3.7/site-packages/sqlalchemy/util/compat.py", line 128, in reraise
    raise value.with_traceback(tb)
  File "/Users/amasics/Documents/Full_Stack_Web_Dev/Fresh-Fyyur/env/lib/python3.7/site-packages/sqlalchemy/engine/base.py", line 1244, in _execute_context
    cursor, statement, parameters, context
  File "/Users/amasics/Documents/Full_Stack_Web_Dev/Fresh-Fyyur/env/lib/python3.7/site-packages/sqlalchemy/engine/default.py", line 552, in do_execute
    cursor.execute(statement, parameters)
sqlalchemy.exc.ProgrammingError: (psycopg2.errors.UndefinedTable) relation "Venue" does not exist
LINE 2: FROM "Venue"
             ^

[SQL: SELECT DISTINCT ON ("Venue".city) "Venue".id AS "Venue_id", "Venue".name AS "Venue_name", "Venue".genres AS "Venue_genres", "Venue".city AS "Venue_city", "Venue".state AS "Venue_state", "Venue".address AS "Venue_address", "Venue".phone AS "Venue_phone", "Venue".website AS "Venue_website", "Venue".image_link AS "Venue_image_link", "Venue".facebook_link AS "Venue_facebook_link", "Venue".seeking_talent AS "Venue_seeking_talent", "Venue".seeking_description AS "Venue_seeking_description" 
FROM "Venue"]
(Background on this error at: http://sqlalche.me/e/f405)
2020-07-12 23:30:18,999 ERROR: Exception on /venues [GET] [in /Users/amasics/Documents/Full_Stack_Web_Dev/Fresh-Fyyur/env/lib/python3.7/site-packages/flask/app.py:1761]
Traceback (most recent call last):
  File "/Users/amasics/Documents/Full_Stack_Web_Dev/Fresh-Fyyur/env/lib/python3.7/site-packages/sqlalchemy/engine/base.py", line 1244, in _execute_context
    cursor, statement, parameters, context
  File "/Users/amasics/Documents/Full_Stack_Web_Dev/Fresh-Fyyur/env/lib/python3.7/site-packages/sqlalchemy/engine/default.py", line 552, in do_execute
    cursor.execute(statement, parameters)
psycopg2.errors.UndefinedTable: relation "Venue" does not exist
LINE 2: FROM "Venue"
             ^


The above exception was the direct cause of the following exception:

Traceback (most recent call last):
  File "/Users/amasics/Documents/Full_Stack_Web_Dev/Fresh-Fyyur/env/lib/python3.7/site-packages/flask/app.py", line 2292, in wsgi_app
    response = self.full_dispatch_request()
  File "/Users/amasics/Documents/Full_Stack_Web_Dev/Fresh-Fyyur/env/lib/python3.7/site-packages/flask/app.py", line 1815, in full_dispatch_request
    rv = self.handle_user_exception(e)
  File "/Users/amasics/Documents/Full_Stack_Web_Dev/Fresh-Fyyur/env/lib/python3.7/site-packages/flask_cors/extension.py", line 161, in wrapped_function
    return cors_after_request(app.make_response(f(*args, **kwargs)))
  File "/Users/amasics/Documents/Full_Stack_Web_Dev/Fresh-Fyyur/env/lib/python3.7/site-packages/flask/app.py", line 1718, in handle_user_exception
    reraise(exc_type, exc_value, tb)
  File "/Users/amasics/Documents/Full_Stack_Web_Dev/Fresh-Fyyur/env/lib/python3.7/site-packages/flask/_compat.py", line 35, in reraise
    raise value
  File "/Users/amasics/Documents/Full_Stack_Web_Dev/Fresh-Fyyur/env/lib/python3.7/site-packages/flask/app.py", line 1813, in full_dispatch_request
    rv = self.dispatch_request()
  File "/Users/amasics/Documents/Full_Stack_Web_Dev/Fresh-Fyyur/env/lib/python3.7/site-packages/flask/app.py", line 1799, in dispatch_request
    return self.view_functions[rule.endpoint](**req.view_args)
  File "/Users/amasics/Documents/Full_Stack_Web_Dev/Fresh-Fyyur/backend/app.py", line 67, in venues
    cities = Venue.query.distinct('city').all()
  File "/Users/amasics/Documents/Full_Stack_Web_Dev/Fresh-Fyyur/env/lib/python3.7/site-packages/sqlalchemy/orm/query.py", line 3161, in all
    return list(self)
  File "/Users/amasics/Documents/Full_Stack_Web_Dev/Fresh-Fyyur/env/lib/python3.7/site-packages/sqlalchemy/orm/query.py", line 3317, in __iter__
    return self._execute_and_instances(context)
  File "/Users/amasics/Documents/Full_Stack_Web_Dev/Fresh-Fyyur/env/lib/python3.7/site-packages/sqlalchemy/orm/query.py", line 3342, in _execute_and_instances
    result = conn.execute(querycontext.statement, self._params)
  File "/Users/amasics/Documents/Full_Stack_Web_Dev/Fresh-Fyyur/env/lib/python3.7/site-packages/sqlalchemy/engine/base.py", line 988, in execute
    return meth(self, multiparams, params)
  File "/Users/amasics/Documents/Full_Stack_Web_Dev/Fresh-Fyyur/env/lib/python3.7/site-packages/sqlalchemy/sql/elements.py", line 287, in _execute_on_connection
    return connection._execute_clauseelement(self, multiparams, params)
  File "/Users/amasics/Documents/Full_Stack_Web_Dev/Fresh-Fyyur/env/lib/python3.7/site-packages/sqlalchemy/engine/base.py", line 1107, in _execute_clauseelement
    distilled_params,
  File "/Users/amasics/Documents/Full_Stack_Web_Dev/Fresh-Fyyur/env/lib/python3.7/site-packages/sqlalchemy/engine/base.py", line 1248, in _execute_context
    e, statement, parameters, cursor, context
  File "/Users/amasics/Documents/Full_Stack_Web_Dev/Fresh-Fyyur/env/lib/python3.7/site-packages/sqlalchemy/engine/base.py", line 1466, in _handle_dbapi_exception
    util.raise_from_cause(sqlalchemy_exception, exc_info)
  File "/Users/amasics/Documents/Full_Stack_Web_Dev/Fresh-Fyyur/env/lib/python3.7/site-packages/sqlalchemy/util/compat.py", line 383, in raise_from_cause
    reraise(type(exception), exception, tb=exc_tb, cause=cause)
  File "/Users/amasics/Documents/Full_Stack_Web_Dev/Fresh-Fyyur/env/lib/python3.7/site-packages/sqlalchemy/util/compat.py", line 128, in reraise
    raise value.with_traceback(tb)
  File "/Users/amasics/Documents/Full_Stack_Web_Dev/Fresh-Fyyur/env/lib/python3.7/site-packages/sqlalchemy/engine/base.py", line 1244, in _execute_context
    cursor, statement, parameters, context
  File "/Users/amasics/Documents/Full_Stack_Web_Dev/Fresh-Fyyur/env/lib/python3.7/site-packages/sqlalchemy/engine/default.py", line 552, in do_execute
    cursor.execute(statement, parameters)
sqlalchemy.exc.ProgrammingError: (psycopg2.errors.UndefinedTable) relation "Venue" does not exist
LINE 2: FROM "Venue"
             ^

[SQL: SELECT DISTINCT ON ("Venue".city) "Venue".id AS "Venue_id", "Venue".name AS "Venue_name", "Venue".genres AS "Venue_genres", "Venue".city AS "Venue_city", "Venue".state AS "Venue_state", "Venue".address AS "Venue_address", "Venue".phone AS "Venue_phone", "Venue".website AS "Venue_website", "Venue".image_link AS "Venue_image_link", "Venue".facebook_link AS "Venue_facebook_link", "Venue".seeking_talent AS "Venue_seeking_talent", "Venue".seeking_description AS "Venue_seeking_description" 
FROM "Venue"]
(Background on this error at: http://sqlalche.me/e/f405)
2020-07-12 23:31:23,797 INFO: errors [in /Users/amasics/Documents/Full_Stack_Web_Dev/Fresh-Fyyur/backend/app.py:452]
2020-07-12 23:31:27,654 INFO: errors [in /Users/amasics/Documents/Full_Stack_Web_Dev/Fresh-Fyyur/backend/app.py:452]
2020-07-12 23:31:43,515 INFO: errors [in /Users/amasics/Documents/Full_Stack_Web_Dev/Fresh-Fyyur/backend/app.py:452]
2020-07-12 23:31:58,775 INFO: errors [in /Users/amasics/Documents/Full_Stack_Web_Dev/Fresh-Fyyur/backend/app.py:452]
2020-07-12 23:33:09,442 INFO: errors [in /Users/amasics/Documents/Full_Stack_Web_Dev/Fresh-Fyyur/backend/app.py:452]
2020-07-12 23:33:09,796 INFO: errors [in /Users/amasics/Documents/Full_Stack_Web_Dev/Fresh-Fyyur/backend/app.py:452]
